07/08/2022 10:37:27|WARNING |apscheduler.executors.default   |Run time of job "Sync episodes with Sonarr (trigger: interval[1:00:00], next run at: 2022-08-07 11:26:18 -05)" was missed by 0:11:09.359009|
07/08/2022 10:37:27|WARNING |apscheduler.executors.default   |Run time of job "Update Series list from Sonarr (trigger: interval[1:00:00], next run at: 2022-08-07 11:27:27 -05)" was missed by 0:10:00.364288|
07/08/2022 10:37:27|WARNING |apscheduler.executors.default   |Run time of job "Update Movie list from Radarr (trigger: interval[1:00:00], next run at: 2022-08-07 11:25:00 -05)" was missed by 0:12:27.354275|
07/08/2022 10:37:27|WARNING |apscheduler.executors.default   |Run time of job "Search for wanted Series Subtitles (trigger: interval[3:00:00], next run at: 2022-08-07 12:04:31 -05)" was missed by 1:32:56.367093|
07/08/2022 10:37:27|WARNING |apscheduler.executors.default   |Run time of job "Check health (trigger: interval[6:00:00], next run at: 2022-08-07 15:16:38 -05)" was missed by 1:20:49.369000|
07/08/2022 10:37:27|WARNING |apscheduler.executors.default   |Run time of job "Search for wanted Movies Subtitles (trigger: interval[3:00:00], next run at: 2022-08-07 12:19:25 -05)" was missed by 1:18:02.370847|
07/08/2022 10:37:27|WARNING |apscheduler.executors.default   |Run time of job "Update Release Info (trigger: interval[3:00:00], next run at: 2022-08-07 12:22:07 -05)" was missed by 1:15:20.374172|
07/08/2022 10:37:27|WARNING |apscheduler.executors.default   |Run time of job "Upgrade previously downloaded Subtitles (trigger: interval[12:00:00], next run at: 2022-08-07 12:59:59 -05)" was missed by 9:37:28.374365|
07/08/2022 10:37:27|WARNING |apscheduler.executors.default   |Run time of job "Backup database and configuration file (trigger: cron[day_of_week='6', hour='3'], next run at: 2022-08-14 03:00:00 -05)" was missed by 7:37:27.949438|
07/08/2022 10:37:27|WARNING |apscheduler.executors.default   |Run time of job "Update all Episode Subtitles from disk (trigger: cron[hour='4'], next run at: 2022-08-08 04:00:00 -05)" was missed by 6:37:27.951547|
07/08/2022 10:37:28|WARNING |apscheduler.executors.default   |Run time of job "Update all Movie Subtitles from disk (trigger: cron[hour='5'], next run at: 2022-08-08 05:00:00 -05)" was missed by 5:37:28.000955|
07/08/2022 11:44:59|INFO    |root                            |BAZARR trying to connect to Sonarr SignalR feed...|
07/08/2022 11:44:59|INFO    |root                            |BAZARR trying to connect to Radarr SignalR feed...|
07/08/2022 11:44:59|INFO    |root                            |BAZARR is started and waiting for request on http://***.***.***.***:6767|
07/08/2022 11:44:59|INFO    |root                            |BAZARR SignalR client for Radarr is connected and waiting for events.|
07/08/2022 11:45:00|INFO    |root                            |BAZARR SignalR client for Sonarr is connected and waiting for events.|
07/08/2022 12:02:46|ERROR   |root                            |BAZARR SignalR client for Radarr connection as been lost. Trying to reconnect...|
07/08/2022 12:31:19|ERROR   |root                            |BAZARR Error trying to get rootfolder from Sonarr. Connection Error.|'Traceback (most recent call last):\n  File "/app/bazarr/bin/bazarr/../libs/urllib3/connection.py", line 174, in _new_conn\n    conn = connection.create_connection(\n  File "/app/bazarr/bin/bazarr/../libs/subliminal_patch/http.py", line 325, in patched_create_connection\n    return _orig_create_connection(address, *args, **kwargs)\n  File "/app/bazarr/bin/bazarr/../libs/urllib3/util/connection.py", line 95, in create_connection\n    raise err\n  File "/app/bazarr/bin/bazarr/../libs/urllib3/util/connection.py", line 85, in create_connection\n    sock.connect(sa)\nsocket.timeout: timed out\n\nDuring handling of the above exception, another exception occurred:\n\nTraceback (most recent call last):\n  File "/app/bazarr/bin/bazarr/../libs/urllib3/connectionpool.py", line 703, in urlopen\n    httplib_response = self._make_request(\n  File "/app/bazarr/bin/bazarr/../libs/urllib3/connectionpool.py", line 398, in _make_request\n    conn.request(method, url, **httplib_request_kw)\n  File "/app/bazarr/bin/bazarr/../libs/urllib3/connection.py", line 239, in request\n    super(HTTPConnection, self).request(method, url, body=body, headers=headers)\n  File "/usr/lib/python3.9/http/client.py", line 1253, in request\n    self._send_request(method, url, body, headers, encode_chunked)\n  File "/usr/lib/python3.9/http/client.py", line 1299, in _send_request\n    self.endheaders(body, encode_chunked=encode_chunked)\n  File "/usr/lib/python3.9/http/client.py", line 1248, in endheaders\n    self._send_output(message_body, encode_chunked=encode_chunked)\n  File "/usr/lib/python3.9/http/client.py", line 1008, in _send_output\n    self.send(msg)\n  File "/usr/lib/python3.9/http/client.py", line 948, in send\n    self.connect()\n  File "/app/bazarr/bin/bazarr/../libs/urllib3/connection.py", line 205, in connect\n    conn = self._new_conn()\n  File "/app/bazarr/bin/bazarr/../libs/urllib3/connection.py", line 179, in _new_conn\n    raise ConnectTimeoutError(\nurllib3.exceptions.ConnectTimeoutError: (<urllib3.connection.HTTPConnection object at 0x7f6f3d69e850>, \'Connection to ***.***.***.*** timed out. (connect timeout=60)\')\n\nDuring handling of the above exception, another exception occurred:\n\nTraceback (most recent call last):\n  File "/app/bazarr/bin/bazarr/../libs/requests/adapters.py", line 440, in send\n    resp = conn.urlopen(\n  File "/app/bazarr/bin/bazarr/../libs/urllib3/connectionpool.py", line 785, in urlopen\n    retries = retries.increment(\n  File "/app/bazarr/bin/bazarr/../libs/urllib3/util/retry.py", line 592, in increment\n    raise MaxRetryError(_pool, url, error or ResponseError(cause))\nurllib3.exceptions.MaxRetryError: HTTPConnectionPool(host=\'***.***.***.***\', port=8989): Max retries exceeded with url: /tv/api/v3/rootfolder?apikey=(removed) (Caused by ConnectTimeoutError(<urllib3.connection.HTTPConnection object at 0x7f6f3d69e850>, \'Connection to ***.***.***.*** timed out. (connect timeout=60)\'))\n\nDuring handling of the above exception, another exception occurred:\n\nTraceback (most recent call last):\n  File "/app/bazarr/bin/bazarr/sonarr/rootfolder.py", line 25, in get_sonarr_rootfolder\n    rootfolder = requests.get(url_sonarr_api_rootfolder, timeout=60, verify=False, headers=headers)\n  File "/app/bazarr/bin/bazarr/../libs/requests/api.py", line 75, in get\n    return request(\'get\', url, params=params, **kwargs)\n  File "/app/bazarr/bin/bazarr/../libs/requests/api.py", line 61, in request\n    return session.request(method=method, url=url, **kwargs)\n  File "/app/bazarr/bin/bazarr/../libs/requests/sessions.py", line 529, in request\n    resp = self.send(prep, **send_kwargs)\n  File "/app/bazarr/bin/bazarr/../libs/requests/sessions.py", line 645, in send\n    r = adapter.send(request, **kwargs)\n  File "/app/bazarr/bin/bazarr/../libs/requests/adapters.py", line 507, in send\n    raise ConnectTimeout(e, request=request)\nrequests.exceptions.ConnectTimeout: HTTPConnectionPool(host=\'***.***.***.***\', port=8989): Max retries exceeded with url: /tv/api/v3/rootfolder?apikey=(removed) (Caused by ConnectTimeoutError(<urllib3.connection.HTTPConnection object at 0x7f6f3d69e850>, \'Connection to ***.***.***.*** timed out. (connect timeout=60)\'))'|
07/08/2022 12:32:19|ERROR   |root                            |BAZARR Error trying to get profiles from Sonarr. Connection Error.|'Traceback (most recent call last):\n  File "/app/bazarr/bin/bazarr/../libs/urllib3/connection.py", line 174, in _new_conn\n    conn = connection.create_connection(\n  File "/app/bazarr/bin/bazarr/../libs/subliminal_patch/http.py", line 325, in patched_create_connection\n    return _orig_create_connection(address, *args, **kwargs)\n  File "/app/bazarr/bin/bazarr/../libs/urllib3/util/connection.py", line 95, in create_connection\n    raise err\n  File "/app/bazarr/bin/bazarr/../libs/urllib3/util/connection.py", line 85, in create_connection\n    sock.connect(sa)\nOSError: [Errno 113] Host is unreachable\n\nDuring handling of the above exception, another exception occurred:\n\nTraceback (most recent call last):\n  File "/app/bazarr/bin/bazarr/../libs/urllib3/connectionpool.py", line 703, in urlopen\n    httplib_response = self._make_request(\n  File "/app/bazarr/bin/bazarr/../libs/urllib3/connectionpool.py", line 398, in _make_request\n    conn.request(method, url, **httplib_request_kw)\n  File "/app/bazarr/bin/bazarr/../libs/urllib3/connection.py", line 239, in request\n    super(HTTPConnection, self).request(method, url, body=body, headers=headers)\n  File "/usr/lib/python3.9/http/client.py", line 1253, in request\n    self._send_request(method, url, body, headers, encode_chunked)\n  File "/usr/lib/python3.9/http/client.py", line 1299, in _send_request\n    self.endheaders(body, encode_chunked=encode_chunked)\n  File "/usr/lib/python3.9/http/client.py", line 1248, in endheaders\n    self._send_output(message_body, encode_chunked=encode_chunked)\n  File "/usr/lib/python3.9/http/client.py", line 1008, in _send_output\n    self.send(msg)\n  File "/usr/lib/python3.9/http/client.py", line 948, in send\n    self.connect()\n  File "/app/bazarr/bin/bazarr/../libs/urllib3/connection.py", line 205, in connect\n    conn = self._new_conn()\n  File "/app/bazarr/bin/bazarr/../libs/urllib3/connection.py", line 186, in _new_conn\n    raise NewConnectionError(\nurllib3.exceptions.NewConnectionError: <urllib3.connection.HTTPConnection object at 0x7f6f44274a00>: Failed to establish a new connection: [Errno 113] Host is unreachable\n\nDuring handling of the above exception, another exception occurred:\n\nTraceback (most recent call last):\n  File "/app/bazarr/bin/bazarr/../libs/requests/adapters.py", line 440, in send\n    resp = conn.urlopen(\n  File "/app/bazarr/bin/bazarr/../libs/urllib3/connectionpool.py", line 785, in urlopen\n    retries = retries.increment(\n  File "/app/bazarr/bin/bazarr/../libs/urllib3/util/retry.py", line 592, in increment\n    raise MaxRetryError(_pool, url, error or ResponseError(cause))\nurllib3.exceptions.MaxRetryError: HTTPConnectionPool(host=\'***.***.***.***\', port=8989): Max retries exceeded with url: /tv/api/v3/languageprofile?apikey=(removed) (Caused by NewConnectionError(\'<urllib3.connection.HTTPConnection object at 0x7f6f44274a00>: Failed to establish a new connection: [Errno 113] Host is unreachable\'))\n\nDuring handling of the above exception, another exception occurred:\n\nTraceback (most recent call last):\n  File "/app/bazarr/bin/bazarr/sonarr/sync/utils.py", line 22, in get_profile_list\n    profiles_json = requests.get(url_sonarr_api_series, timeout=60, verify=False, headers=headers)\n  File "/app/bazarr/bin/bazarr/../libs/requests/api.py", line 75, in get\n    return request(\'get\', url, params=params, **kwargs)\n  File "/app/bazarr/bin/bazarr/../libs/requests/api.py", line 61, in request\n    return session.request(method=method, url=url, **kwargs)\n  File "/app/bazarr/bin/bazarr/../libs/requests/sessions.py", line 529, in request\n    resp = self.send(prep, **send_kwargs)\n  File "/app/bazarr/bin/bazarr/../libs/requests/sessions.py", line 645, in send\n    r = adapter.send(request, **kwargs)\n  File "/app/bazarr/bin/bazarr/../libs/requests/adapters.py", line 519, in send\n    raise ConnectionError(e, request=request)\nrequests.exceptions.ConnectionError: HTTPConnectionPool(host=\'***.***.***.***\', port=8989): Max retries exceeded with url: /tv/api/v3/languageprofile?apikey=(removed) (Caused by NewConnectionError(\'<urllib3.connection.HTTPConnection object at 0x7f6f44274a00>: Failed to establish a new connection: [Errno 113] Host is unreachable\'))'|
07/08/2022 12:33:19|ERROR   |root                            |BAZARR Error trying to get tags from Sonarr. Connection Error.|'Traceback (most recent call last):\n  File "/app/bazarr/bin/bazarr/../libs/urllib3/connection.py", line 174, in _new_conn\n    conn = connection.create_connection(\n  File "/app/bazarr/bin/bazarr/../libs/subliminal_patch/http.py", line 325, in patched_create_connection\n    return _orig_create_connection(address, *args, **kwargs)\n  File "/app/bazarr/bin/bazarr/../libs/urllib3/util/connection.py", line 95, in create_connection\n    raise err\n  File "/app/bazarr/bin/bazarr/../libs/urllib3/util/connection.py", line 85, in create_connection\n    sock.connect(sa)\nsocket.timeout: timed out\n\nDuring handling of the above exception, another exception occurred:\n\nTraceback (most recent call last):\n  File "/app/bazarr/bin/bazarr/../libs/urllib3/connectionpool.py", line 703, in urlopen\n    httplib_response = self._make_request(\n  File "/app/bazarr/bin/bazarr/../libs/urllib3/connectionpool.py", line 398, in _make_request\n    conn.request(method, url, **httplib_request_kw)\n  File "/app/bazarr/bin/bazarr/../libs/urllib3/connection.py", line 239, in request\n    super(HTTPConnection, self).request(method, url, body=body, headers=headers)\n  File "/usr/lib/python3.9/http/client.py", line 1253, in request\n    self._send_request(method, url, body, headers, encode_chunked)\n  File "/usr/lib/python3.9/http/client.py", line 1299, in _send_request\n    self.endheaders(body, encode_chunked=encode_chunked)\n  File "/usr/lib/python3.9/http/client.py", line 1248, in endheaders\n    self._send_output(message_body, encode_chunked=encode_chunked)\n  File "/usr/lib/python3.9/http/client.py", line 1008, in _send_output\n    self.send(msg)\n  File "/usr/lib/python3.9/http/client.py", line 948, in send\n    self.connect()\n  File "/app/bazarr/bin/bazarr/../libs/urllib3/connection.py", line 205, in connect\n    conn = self._new_conn()\n  File "/app/bazarr/bin/bazarr/../libs/urllib3/connection.py", line 179, in _new_conn\n    raise ConnectTimeoutError(\nurllib3.exceptions.ConnectTimeoutError: (<urllib3.connection.HTTPConnection object at 0x7f6f3bbf33a0>, \'Connection to ***.***.***.*** timed out. (connect timeout=60)\')\n\nDuring handling of the above exception, another exception occurred:\n\nTraceback (most recent call last):\n  File "/app/bazarr/bin/bazarr/../libs/requests/adapters.py", line 440, in send\n    resp = conn.urlopen(\n  File "/app/bazarr/bin/bazarr/../libs/urllib3/connectionpool.py", line 785, in urlopen\n    retries = retries.increment(\n  File "/app/bazarr/bin/bazarr/../libs/urllib3/util/retry.py", line 592, in increment\n    raise MaxRetryError(_pool, url, error or ResponseError(cause))\nurllib3.exceptions.MaxRetryError: HTTPConnectionPool(host=\'***.***.***.***\', port=8989): Max retries exceeded with url: /tv/api/v3/tag?apikey=(removed) (Caused by ConnectTimeoutError(<urllib3.connection.HTTPConnection object at 0x7f6f3bbf33a0>, \'Connection to ***.***.***.*** timed out. (connect timeout=60)\'))\n\nDuring handling of the above exception, another exception occurred:\n\nTraceback (most recent call last):\n  File "/app/bazarr/bin/bazarr/sonarr/sync/utils.py", line 55, in get_tags\n    tagsDict = requests.get(url_sonarr_api_series, timeout=60, verify=False, headers=headers)\n  File "/app/bazarr/bin/bazarr/../libs/requests/api.py", line 75, in get\n    return request(\'get\', url, params=params, **kwargs)\n  File "/app/bazarr/bin/bazarr/../libs/requests/api.py", line 61, in request\n    return session.request(method=method, url=url, **kwargs)\n  File "/app/bazarr/bin/bazarr/../libs/requests/sessions.py", line 529, in request\n    resp = self.send(prep, **send_kwargs)\n  File "/app/bazarr/bin/bazarr/../libs/requests/sessions.py", line 645, in send\n    r = adapter.send(request, **kwargs)\n  File "/app/bazarr/bin/bazarr/../libs/requests/adapters.py", line 507, in send\n    raise ConnectTimeout(e, request=request)\nrequests.exceptions.ConnectTimeout: HTTPConnectionPool(host=\'***.***.***.***\', port=8989): Max retries exceeded with url: /tv/api/v3/tag?apikey=(removed) (Caused by ConnectTimeoutError(<urllib3.connection.HTTPConnection object at 0x7f6f3bbf33a0>, \'Connection to ***.***.***.*** timed out. (connect timeout=60)\'))'|
07/08/2022 12:34:20|ERROR   |root                            |BAZARR Error trying to get series from Sonarr. Connection Error.|'Traceback (most recent call last):\n  File "/app/bazarr/bin/bazarr/../libs/urllib3/connection.py", line 174, in _new_conn\n    conn = connection.create_connection(\n  File "/app/bazarr/bin/bazarr/../libs/subliminal_patch/http.py", line 325, in patched_create_connection\n    return _orig_create_connection(address, *args, **kwargs)\n  File "/app/bazarr/bin/bazarr/../libs/urllib3/util/connection.py", line 95, in create_connection\n    raise err\n  File "/app/bazarr/bin/bazarr/../libs/urllib3/util/connection.py", line 85, in create_connection\n    sock.connect(sa)\nsocket.timeout: timed out\n\nDuring handling of the above exception, another exception occurred:\n\nTraceback (most recent call last):\n  File "/app/bazarr/bin/bazarr/../libs/urllib3/connectionpool.py", line 703, in urlopen\n    httplib_response = self._make_request(\n  File "/app/bazarr/bin/bazarr/../libs/urllib3/connectionpool.py", line 398, in _make_request\n    conn.request(method, url, **httplib_request_kw)\n  File "/app/bazarr/bin/bazarr/../libs/urllib3/connection.py", line 239, in request\n    super(HTTPConnection, self).request(method, url, body=body, headers=headers)\n  File "/usr/lib/python3.9/http/client.py", line 1253, in request\n    self._send_request(method, url, body, headers, encode_chunked)\n  File "/usr/lib/python3.9/http/client.py", line 1299, in _send_request\n    self.endheaders(body, encode_chunked=encode_chunked)\n  File "/usr/lib/python3.9/http/client.py", line 1248, in endheaders\n    self._send_output(message_body, encode_chunked=encode_chunked)\n  File "/usr/lib/python3.9/http/client.py", line 1008, in _send_output\n    self.send(msg)\n  File "/usr/lib/python3.9/http/client.py", line 948, in send\n    self.connect()\n  File "/app/bazarr/bin/bazarr/../libs/urllib3/connection.py", line 205, in connect\n    conn = self._new_conn()\n  File "/app/bazarr/bin/bazarr/../libs/urllib3/connection.py", line 179, in _new_conn\n    raise ConnectTimeoutError(\nurllib3.exceptions.ConnectTimeoutError: (<urllib3.connection.HTTPConnection object at 0x7f6f3d6598e0>, \'Connection to ***.***.***.*** timed out. (connect timeout=60)\')\n\nDuring handling of the above exception, another exception occurred:\n\nTraceback (most recent call last):\n  File "/app/bazarr/bin/bazarr/../libs/requests/adapters.py", line 440, in send\n    resp = conn.urlopen(\n  File "/app/bazarr/bin/bazarr/../libs/urllib3/connectionpool.py", line 785, in urlopen\n    retries = retries.increment(\n  File "/app/bazarr/bin/bazarr/../libs/urllib3/util/retry.py", line 592, in increment\n    raise MaxRetryError(_pool, url, error or ResponseError(cause))\nurllib3.exceptions.MaxRetryError: HTTPConnectionPool(host=\'***.***.***.***\', port=8989): Max retries exceeded with url: /tv/api/v3/series/?apikey=(removed) (Caused by ConnectTimeoutError(<urllib3.connection.HTTPConnection object at 0x7f6f3d6598e0>, \'Connection to ***.***.***.*** timed out. (connect timeout=60)\'))\n\nDuring handling of the above exception, another exception occurred:\n\nTraceback (most recent call last):\n  File "/app/bazarr/bin/bazarr/sonarr/sync/utils.py", line 73, in get_series_from_sonarr_api\n    r = requests.get(url_sonarr_api_series, timeout=60, verify=False, headers=headers)\n  File "/app/bazarr/bin/bazarr/../libs/requests/api.py", line 75, in get\n    return request(\'get\', url, params=params, **kwargs)\n  File "/app/bazarr/bin/bazarr/../libs/requests/api.py", line 61, in request\n    return session.request(method=method, url=url, **kwargs)\n  File "/app/bazarr/bin/bazarr/../libs/requests/sessions.py", line 529, in request\n    resp = self.send(prep, **send_kwargs)\n  File "/app/bazarr/bin/bazarr/../libs/requests/sessions.py", line 645, in send\n    r = adapter.send(request, **kwargs)\n  File "/app/bazarr/bin/bazarr/../libs/requests/adapters.py", line 507, in send\n    raise ConnectTimeout(e, request=request)\nrequests.exceptions.ConnectTimeout: HTTPConnectionPool(host=\'***.***.***.***\', port=8989): Max retries exceeded with url: /tv/api/v3/series/?apikey=(removed) (Caused by ConnectTimeoutError(<urllib3.connection.HTTPConnection object at 0x7f6f3d6598e0>, \'Connection to ***.***.***.*** timed out. (connect timeout=60)\'))'|
07/08/2022 12:38:52|INFO    |root                            |BAZARR SignalR client for Radarr is connected and waiting for events.|
07/08/2022 12:38:53|INFO    |root                            |BAZARR SignalR client for Radarr is connected and waiting for events.|
07/08/2022 12:39:02|INFO    |root                            |BAZARR SignalR client for Radarr is connected and waiting for events.|
07/08/2022 12:39:08|ERROR   |root                            |BAZARR SignalR client for Radarr connection as been lost. Trying to reconnect...|
07/08/2022 12:39:08|INFO    |root                            |BAZARR SignalR client for Radarr is connected and waiting for events.|
07/08/2022 12:39:19|INFO    |root                            |BAZARR SignalR client for Radarr is connected and waiting for events.|
07/08/2022 22:30:40|WARNING |apscheduler.executors.default   |Run time of job "Update Movie list from Radarr (trigger: interval[1:00:00], next run at: 2022-08-07 22:42:11 -05)" was missed by 0:48:29.087326|
07/08/2022 22:30:40|WARNING |apscheduler.executors.default   |Run time of job "Update Series list from Sonarr (trigger: interval[1:00:00], next run at: 2022-08-07 23:30:08 -05)" was missed by 0:00:32.081068|
07/08/2022 22:30:41|WARNING |apscheduler.executors.default   |Run time of job "Sync episodes with Sonarr (trigger: interval[1:00:00], next run at: 2022-08-07 22:44:16 -05)" was missed by 0:46:24.095002|
07/08/2022 22:30:41|WARNING |apscheduler.executors.default   |Run time of job "Search for wanted Movies Subtitles (trigger: interval[3:00:00], next run at: 2022-08-07 23:01:43 -05)" was missed by 2:28:57.095469|
07/08/2022 22:30:41|WARNING |apscheduler.executors.default   |Run time of job "Search for wanted Series Subtitles (trigger: interval[3:00:00], next run at: 2022-08-07 23:09:54 -05)" was missed by 2:20:46.102714|
07/08/2022 22:30:41|WARNING |apscheduler.executors.default   |Run time of job "Update Release Info (trigger: interval[3:00:00], next run at: 2022-08-07 23:20:32 -05)" was missed by 2:10:08.105404|
07/08/2022 22:30:41|WARNING |apscheduler.executors.default   |Run time of job "Check health (trigger: interval[6:00:00], next run at: 2022-08-07 23:18:57 -05)" was missed by 5:11:43.108056|
07/08/2022 22:30:41|WARNING |apscheduler.executors.default   |Run time of job "Upgrade previously downloaded Subtitles (trigger: interval[12:00:00], next run at: 2022-08-08 09:24:44 -05)" was missed by 1:05:56.109243|
07/08/2022 22:42:52|INFO    |root                            |BAZARR trying to connect to Sonarr SignalR feed...|
07/08/2022 22:42:52|INFO    |root                            |BAZARR trying to connect to Radarr SignalR feed...|
07/08/2022 22:42:52|INFO    |root                            |BAZARR is started and waiting for request on http://***.***.***.***:6767|
07/08/2022 22:42:52|INFO    |root                            |BAZARR SignalR client for Radarr is connected and waiting for events.|
07/08/2022 22:42:52|INFO    |root                            |BAZARR SignalR client for Sonarr is connected and waiting for events.|
07/08/2022 22:47:51|INFO    |root                            |BAZARR trying to connect to Sonarr SignalR feed...|
07/08/2022 22:47:51|INFO    |root                            |BAZARR trying to connect to Radarr SignalR feed...|
07/08/2022 22:47:51|INFO    |root                            |BAZARR is started and waiting for request on http://***.***.***.***:6767|
07/08/2022 22:47:51|INFO    |root                            |BAZARR SignalR client for Sonarr is connected and waiting for events.|
07/08/2022 22:47:51|INFO    |root                            |BAZARR SignalR client for Radarr is connected and waiting for events.|
07/08/2022 22:54:48|INFO    |root                            |Using sucha again after 1 hour, (disabled because: ConnectTimeout)|
