04/08/2022 00:06:39|INFO    |root                            |Throttling subscene for 10 minutes, until 22/08/04 00:16, because of: ProviderError. Exception info: 'Something went wrong when trying to log in #1'|
04/08/2022 00:09:42|WARNING |retry.api                       |HTTPSConnectionPool(host='argenteam.net', port=443): Read timed out. (read timeout=10), retrying in 5 seconds...|
04/08/2022 00:09:52|WARNING |retry.api                       |HTTPSConnectionPool(host='www.subdivx.com', port=443): Read timed out. (read timeout=20), retrying in 5 seconds...|
04/08/2022 00:10:02|INFO    |root                            |BAZARR Finished searching for Subtitles to upgrade. Check History for more information.|
04/08/2022 00:11:23|INFO    |root                            |BAZARR Finished searching for missing Series Subtitles. Check History for more information.|
04/08/2022 02:34:57|INFO    |root                            |Using sucha again after 1 hour, (disabled because: ConnectTimeout)|
04/08/2022 02:34:57|INFO    |root                            |Using subscene again after 10 minutes, (disabled because: ProviderError)|
04/08/2022 02:35:07|WARNING |retry.api                       |HTTPSConnectionPool(host='argenteam.net', port=443): Read timed out. (read timeout=10), retrying in 5 seconds...|
04/08/2022 02:35:11|WARNING |retry.api                       |HTTPConnectionPool(host='sapidb.caretas.club', port=80): Max retries exceeded with url: /episode?query=Steins%3BGate+S01E01 (Caused by ConnectTimeoutError(<urllib3.connection.HTTPConnection object at 0x7feea4c312b0>, 'Connection to sapidb.caretas.club timed out. (connect timeout=10)')), retrying in 5 seconds...|
04/08/2022 02:35:17|WARNING |retry.api                       |HTTPSConnectionPool(host='www.subdivx.com', port=443): Read timed out. (read timeout=20), retrying in 5 seconds...|
04/08/2022 02:35:30|WARNING |retry.api                       |HTTPConnectionPool(host='sapidb.caretas.club', port=80): Max retries exceeded with url: /episode?query=Steins%3BGate+S01E01 (Caused by ConnectTimeoutError(<urllib3.connection.HTTPConnection object at 0x7feea2a29700>, 'Connection to sapidb.caretas.club timed out. (connect timeout=10)')), retrying in 5 seconds...|
04/08/2022 02:35:50|INFO    |root                            |Throttling sucha for 1 hour, until 22/08/04 03:35, because of: ConnectTimeout. Exception info: MaxRetryError("HTTPConnectionPool(host='sapidb.caretas.club', port=80): Max retries exceeded with url: /episode?query=Steins%3BGate+S01E01 (Caused by ConnectTimeoutError(<urllib3.connection.HTTPConnection object at 0x7feea651b3a0>, 'Connection to sapidb.caretas.club timed out. (connect timeout=10)'))")|
04/08/2022 02:37:58|WARNING |retry.api                       |HTTPSConnectionPool(host='www.subtitulamos.tv', port=443): Read timed out. (read timeout=10), retrying in 5 seconds...|
04/08/2022 02:46:10|INFO    |root                            |BAZARR Finished searching for missing Movies Subtitles. Check History for more information.|
04/08/2022 02:48:55|INFO    |root                            |Throttling subscene for 10 minutes, until 22/08/04 02:58, because of: ProviderError. Exception info: 'Something went wrong when trying to log in #1'|
04/08/2022 02:54:56|INFO    |root                            |BAZARR Finished searching for missing Series Subtitles. Check History for more information.|
04/08/2022 04:00:02|INFO    |root                            |BAZARR All existing episode subtitles indexed from disk.|
04/08/2022 05:00:00|INFO    |root                            |BAZARR All existing movie subtitles indexed from disk.|
04/08/2022 05:34:57|INFO    |root                            |Using sucha again after 1 hour, (disabled because: ConnectTimeout)|
04/08/2022 05:34:57|INFO    |root                            |Using subscene again after 10 minutes, (disabled because: ProviderError)|
04/08/2022 05:35:07|WARNING |retry.api                       |HTTPSConnectionPool(host='argenteam.net', port=443): Read timed out. (read timeout=10), retrying in 5 seconds...|
04/08/2022 05:35:11|WARNING |retry.api                       |HTTPConnectionPool(host='sapidb.caretas.club', port=80): Max retries exceeded with url: /episode?query=Steins%3BGate+S01E01 (Caused by ConnectTimeoutError(<urllib3.connection.HTTPConnection object at 0x7feead460ee0>, 'Connection to sapidb.caretas.club timed out. (connect timeout=10)')), retrying in 5 seconds...|
04/08/2022 05:35:17|WARNING |retry.api                       |HTTPSConnectionPool(host='www.subdivx.com', port=443): Read timed out. (read timeout=20), retrying in 5 seconds...|
04/08/2022 05:35:30|WARNING |retry.api                       |HTTPConnectionPool(host='sapidb.caretas.club', port=80): Max retries exceeded with url: /episode?query=Steins%3BGate+S01E01 (Caused by ConnectTimeoutError(<urllib3.connection.HTTPConnection object at 0x7feea20d64f0>, 'Connection to sapidb.caretas.club timed out. (connect timeout=10)')), retrying in 5 seconds...|
04/08/2022 05:35:49|INFO    |root                            |Throttling sucha for 1 hour, until 22/08/04 06:35, because of: ConnectTimeout. Exception info: MaxRetryError("HTTPConnectionPool(host='sapidb.caretas.club', port=80): Max retries exceeded with url: /episode?query=Steins%3BGate+S01E01 (Caused by ConnectTimeoutError(<urllib3.connection.HTTPConnection object at 0x7feea2a2e1f0>, 'Connection to sapidb.caretas.club timed out. (connect timeout=10)'))")|
04/08/2022 05:36:24|WARNING |retry.api                       |HTTPSConnectionPool(host='argenteam.net', port=443): Read timed out. (read timeout=10), retrying in 5 seconds...|
04/08/2022 05:38:06|INFO    |root                            |Throttling subscene for 10 minutes, until 22/08/04 05:48, because of: ProviderError. Exception info: 'Something went wrong when trying to log in #1'|
04/08/2022 05:38:12|WARNING |retry.api                       |HTTPSConnectionPool(host='www.subtitulamos.tv', port=443): Read timed out. (read timeout=10), retrying in 5 seconds...|
04/08/2022 05:46:10|INFO    |root                            |BAZARR Finished searching for missing Movies Subtitles. Check History for more information.|
04/08/2022 05:46:55|INFO    |root                            |BAZARR Finished searching for missing Series Subtitles. Check History for more information.|
04/08/2022 07:38:14|INFO    |root                            |Using sucha again after 1 hour, (disabled because: ConnectTimeout)|
04/08/2022 07:38:14|INFO    |root                            |Using subscene again after 10 minutes, (disabled because: ProviderError)|
04/08/2022 07:38:32|INFO    |root                            |Throttling subscene for 10 minutes, until 22/08/04 07:48, because of: ProviderError. Exception info: 'Something went wrong when trying to log in #1'|
04/08/2022 07:38:37|WARNING |retry.api                       |HTTPSConnectionPool(host='argenteam.net', port=443): Read timed out. (read timeout=10), retrying in 5 seconds...|
04/08/2022 07:38:37|WARNING |retry.api                       |HTTPSConnectionPool(host='www.subtitulamos.tv', port=443): Read timed out. (read timeout=10), retrying in 5 seconds...|
04/08/2022 07:38:41|WARNING |retry.api                       |HTTPConnectionPool(host='sapidb.caretas.club', port=80): Max retries exceeded with url: /episode?query=Miss+Kobayashi%27s+Dragon+Maid+S01E01 (Caused by ConnectTimeoutError(<urllib3.connection.HTTPConnection object at 0x7feea3654130>, 'Connection to sapidb.caretas.club timed out. (connect timeout=10)')), retrying in 5 seconds...|
04/08/2022 07:38:47|WARNING |retry.api                       |HTTPSConnectionPool(host='www.subdivx.com', port=443): Read timed out. (read timeout=20), retrying in 5 seconds...|
04/08/2022 07:39:00|WARNING |retry.api                       |HTTPConnectionPool(host='sapidb.caretas.club', port=80): Max retries exceeded with url: /episode?query=Miss+Kobayashi%27s+Dragon+Maid+S01E01 (Caused by ConnectTimeoutError(<urllib3.connection.HTTPConnection object at 0x7feea43324c0>, 'Connection to sapidb.caretas.club timed out. (connect timeout=10)')), retrying in 5 seconds...|
04/08/2022 07:39:20|INFO    |root                            |Throttling sucha for 1 hour, until 22/08/04 08:39, because of: ConnectTimeout. Exception info: MaxRetryError("HTTPConnectionPool(host='sapidb.caretas.club', port=80): Max retries exceeded with url: /episode?query=Miss+Kobayashi%27s+Dragon+Maid+S01E01 (Caused by ConnectTimeoutError(<urllib3.connection.HTTPConnection object at 0x7feea2527670>, 'Connection to sapidb.caretas.club timed out. (connect timeout=10)'))")|
04/08/2022 07:53:26|ERROR   |waitress                        |Exception while serving /api/socket.io/|'Traceback (most recent call last):\n  File "/app/bazarr/bin/bazarr/../libs/waitress/channel.py", line 397, in service\n    task.service()\n  File "/app/bazarr/bin/bazarr/../libs/waitress/task.py", line 168, in service\n    self.execute()\n  File "/app/bazarr/bin/bazarr/../libs/waitress/task.py", line 434, in execute\n    app_iter = self.channel.server.application(environ, start_response)\n  File "/app/bazarr/bin/bazarr/../libs/flask/app.py", line 2091, in __call__\n    return self.wsgi_app(environ, start_response)\n  File "/app/bazarr/bin/bazarr/../libs/flask_socketio/__init__.py", line 43, in __call__\n    return super(_SocketIOMiddleware, self).__call__(environ,\n  File "/app/bazarr/bin/bazarr/../libs/engineio/middleware.py", line 63, in __call__\n    return self.engineio_app.handle_request(environ, start_response)\n  File "/app/bazarr/bin/bazarr/../libs/socketio/server.py", line 597, in handle_request\n    return self.eio.handle_request(environ, start_response)\n  File "/app/bazarr/bin/bazarr/../libs/engineio/server.py", line 409, in handle_request\n    socket = self._get_socket(sid)\n  File "/app/bazarr/bin/bazarr/../libs/engineio/server.py", line 638, in _get_socket\n    raise KeyError(\'Session is disconnected\')\nKeyError: \'Session is disconnected\''|
04/08/2022 07:53:27|INFO    |root                            |Using subscene again after 10 minutes, (disabled because: ProviderError)|
04/08/2022 07:53:37|WARNING |retry.api                       |HTTPSConnectionPool(host='argenteam.net', port=443): Read timed out. (read timeout=10), retrying in 5 seconds...|
04/08/2022 07:53:47|WARNING |retry.api                       |HTTPSConnectionPool(host='www.subdivx.com', port=443): Read timed out. (read timeout=20), retrying in 5 seconds...|
04/08/2022 07:55:25|INFO    |root                            |Throttling subscene for 10 minutes, until 22/08/04 08:05, because of: ProviderError. Exception info: 'Something went wrong when trying to log in #1'|
04/08/2022 07:55:31|WARNING |retry.api                       |HTTPSConnectionPool(host='www.subtitulamos.tv', port=443): Read timed out. (read timeout=10), retrying in 5 seconds...|
04/08/2022 08:22:33|ERROR   |engineio.server                 |Invalid session 3HZC7kG1QUZ6pnNKAAAI (further occurrences of this error will be logged with level INFO)|
04/08/2022 08:22:33|ERROR   |waitress                        |Exception while serving /api/socket.io/|'Traceback (most recent call last):\n  File "/app/bazarr/bin/bazarr/../libs/waitress/channel.py", line 397, in service\n    task.service()\n  File "/app/bazarr/bin/bazarr/../libs/waitress/task.py", line 168, in service\n    self.execute()\n  File "/app/bazarr/bin/bazarr/../libs/waitress/task.py", line 434, in execute\n    app_iter = self.channel.server.application(environ, start_response)\n  File "/app/bazarr/bin/bazarr/../libs/flask/app.py", line 2091, in __call__\n    return self.wsgi_app(environ, start_response)\n  File "/app/bazarr/bin/bazarr/../libs/flask_socketio/__init__.py", line 43, in __call__\n    return super(_SocketIOMiddleware, self).__call__(environ,\n  File "/app/bazarr/bin/bazarr/../libs/engineio/middleware.py", line 63, in __call__\n    return self.engineio_app.handle_request(environ, start_response)\n  File "/app/bazarr/bin/bazarr/../libs/socketio/server.py", line 597, in handle_request\n    return self.eio.handle_request(environ, start_response)\n  File "/app/bazarr/bin/bazarr/../libs/engineio/server.py", line 429, in handle_request\n    socket = self._get_socket(sid)\n  File "/app/bazarr/bin/bazarr/../libs/engineio/server.py", line 638, in _get_socket\n    raise KeyError(\'Session is disconnected\')\nKeyError: \'Session is disconnected\''|
04/08/2022 08:34:57|INFO    |root                            |Using subscene again after 10 minutes, (disabled because: ProviderError)|
04/08/2022 08:35:07|WARNING |retry.api                       |HTTPSConnectionPool(host='argenteam.net', port=443): Read timed out. (read timeout=10), retrying in 5 seconds...|
04/08/2022 08:35:17|WARNING |retry.api                       |HTTPSConnectionPool(host='www.subdivx.com', port=443): Read timed out. (read timeout=20), retrying in 5 seconds...|
04/08/2022 08:37:01|WARNING |retry.api                       |HTTPSConnectionPool(host='argenteam.net', port=443): Read timed out. (read timeout=10), retrying in 5 seconds...|
04/08/2022 08:37:50|WARNING |retry.api                       |HTTPSConnectionPool(host='www.subtitulamos.tv', port=443): Read timed out. (read timeout=10), retrying in 5 seconds...|
04/08/2022 08:38:20|WARNING |retry.api                       |HTTPSConnectionPool(host='subscene.com', port=443): Read timed out. (read timeout=10), retrying in 5 seconds...|
04/08/2022 08:40:26|WARNING |retry.api                       |HTTPSConnectionPool(host='subscene.com', port=443): Read timed out. (read timeout=10), retrying in 5 seconds...|
04/08/2022 08:40:49|INFO    |root                            |Using sucha again after 1 hour, (disabled because: ConnectTimeout)|
04/08/2022 08:41:03|WARNING |retry.api                       |HTTPConnectionPool(host='sapidb.caretas.club', port=80): Max retries exceeded with url: /episode?query=Don%27t+Toy+With+Me%2C+Miss+Nagatoro+S01E09 (Caused by ConnectTimeoutError(<urllib3.connection.HTTPConnection object at 0x7feea39d8d60>, 'Connection to sapidb.caretas.club timed out. (connect timeout=10)')), retrying in 5 seconds...|
04/08/2022 08:41:22|WARNING |retry.api                       |HTTPConnectionPool(host='sapidb.caretas.club', port=80): Max retries exceeded with url: /episode?query=Don%27t+Toy+With+Me%2C+Miss+Nagatoro+S01E09 (Caused by ConnectTimeoutError(<urllib3.connection.HTTPConnection object at 0x7feea365cdc0>, 'Connection to sapidb.caretas.club timed out. (connect timeout=10)')), retrying in 5 seconds...|
04/08/2022 08:41:41|INFO    |root                            |Throttling sucha for 1 hour, until 22/08/04 09:41, because of: ConnectTimeout. Exception info: MaxRetryError("HTTPConnectionPool(host='sapidb.caretas.club', port=80): Max retries exceeded with url: /episode?query=Don%27t+Toy+With+Me%2C+Miss+Nagatoro+S01E09 (Caused by ConnectTimeoutError(<urllib3.connection.HTTPConnection object at 0x7feea365c310>, 'Connection to sapidb.caretas.club timed out. (connect timeout=10)'))")|
04/08/2022 08:46:10|INFO    |root                            |BAZARR Finished searching for missing Movies Subtitles. Check History for more information.|
04/08/2022 09:37:20|WARNING |retry.api                       |HTTPSConnectionPool(host='argenteam.net', port=443): Read timed out. (read timeout=10), retrying in 5 seconds...|
04/08/2022 09:42:15|INFO    |root                            |Using sucha again after 1 hour, (disabled because: ConnectTimeout)|
04/08/2022 09:42:30|WARNING |retry.api                       |HTTPConnectionPool(host='sapidb.caretas.club', port=80): Max retries exceeded with url: /episode?query=Miss+Kobayashi%27s+Dragon+Maid+S01E12 (Caused by ConnectTimeoutError(<urllib3.connection.HTTPConnection object at 0x7feea1b47880>, 'Connection to sapidb.caretas.club timed out. (connect timeout=10)')), retrying in 5 seconds...|
04/08/2022 09:42:49|WARNING |retry.api                       |HTTPConnectionPool(host='sapidb.caretas.club', port=80): Max retries exceeded with url: /episode?query=Miss+Kobayashi%27s+Dragon+Maid+S01E12 (Caused by ConnectTimeoutError(<urllib3.connection.HTTPConnection object at 0x7feea34653d0>, 'Connection to sapidb.caretas.club timed out. (connect timeout=10)')), retrying in 5 seconds...|
04/08/2022 09:43:08|INFO    |root                            |Throttling sucha for 1 hour, until 22/08/04 10:43, because of: ConnectTimeout. Exception info: MaxRetryError("HTTPConnectionPool(host='sapidb.caretas.club', port=80): Max retries exceeded with url: /episode?query=Miss+Kobayashi%27s+Dragon+Maid+S01E12 (Caused by ConnectTimeoutError(<urllib3.connection.HTTPConnection object at 0x7feea4d37250>, 'Connection to sapidb.caretas.club timed out. (connect timeout=10)'))")|
04/08/2022 09:59:07|WARNING |retry.api                       |HTTPSConnectionPool(host='subscene.com', port=443): Read timed out. (read timeout=10), retrying in 5 seconds...|
04/08/2022 09:59:29|INFO    |root                            |BAZARR Finished searching for missing Series Subtitles. Check History for more information.|
04/08/2022 11:34:57|INFO    |root                            |Using sucha again after 1 hour, (disabled because: ConnectTimeout)|
04/08/2022 11:35:07|WARNING |retry.api                       |HTTPSConnectionPool(host='argenteam.net', port=443): Read timed out. (read timeout=10), retrying in 5 seconds...|
04/08/2022 11:35:12|WARNING |retry.api                       |HTTPConnectionPool(host='sapidb.caretas.club', port=80): Max retries exceeded with url: /episode?query=Steins%3BGate+S01E01 (Caused by ConnectTimeoutError(<urllib3.connection.HTTPConnection object at 0x7feea45a99a0>, 'Connection to sapidb.caretas.club timed out. (connect timeout=10)')), retrying in 5 seconds...|
04/08/2022 11:35:17|WARNING |retry.api                       |HTTPSConnectionPool(host='www.subdivx.com', port=443): Read timed out. (read timeout=20), retrying in 5 seconds...|
04/08/2022 11:35:31|WARNING |retry.api                       |HTTPConnectionPool(host='sapidb.caretas.club', port=80): Max retries exceeded with url: /episode?query=Steins%3BGate+S01E01 (Caused by ConnectTimeoutError(<urllib3.connection.HTTPConnection object at 0x7feea4320c70>, 'Connection to sapidb.caretas.club timed out. (connect timeout=10)')), retrying in 5 seconds...|
04/08/2022 11:35:50|INFO    |root                            |Throttling sucha for 1 hour, until 22/08/04 12:35, because of: ConnectTimeout. Exception info: MaxRetryError("HTTPConnectionPool(host='sapidb.caretas.club', port=80): Max retries exceeded with url: /episode?query=Steins%3BGate+S01E01 (Caused by ConnectTimeoutError(<urllib3.connection.HTTPConnection object at 0x7feea45faca0>, 'Connection to sapidb.caretas.club timed out. (connect timeout=10)'))")|
04/08/2022 11:37:49|WARNING |retry.api                       |HTTPSConnectionPool(host='argenteam.net', port=443): Read timed out. (read timeout=10), retrying in 5 seconds...|
04/08/2022 11:38:13|WARNING |retry.api                       |HTTPSConnectionPool(host='www.subtitulamos.tv', port=443): Read timed out. (read timeout=10), retrying in 5 seconds...|
04/08/2022 11:38:21|WARNING |retry.api                       |HTTPSConnectionPool(host='subscene.com', port=443): Read timed out. (read timeout=10), retrying in 5 seconds...|
04/08/2022 11:46:10|INFO    |root                            |BAZARR Finished searching for missing Movies Subtitles. Check History for more information.|
04/08/2022 11:59:02|WARNING |retry.api                       |HTTPSConnectionPool(host='subscene.com', port=443): Read timed out. (read timeout=10), retrying in 5 seconds...|
04/08/2022 12:07:29|INFO    |root                            |Throttling subscene for 10 minutes, until 22/08/04 12:17, because of: HTTPError. Exception info: '409 Client Error: Conflict for url: https://subscene.com/subtitles/searchbytitle'|
04/08/2022 12:09:34|WARNING |retry.api                       |HTTPSConnectionPool(host='www.subtitulamos.tv', port=443): Read timed out. (read timeout=10), retrying in 5 seconds...|
04/08/2022 12:09:44|WARNING |retry.api                       |HTTPSConnectionPool(host='www.subdivx.com', port=443): Read timed out. (read timeout=20), retrying in 5 seconds...|
04/08/2022 12:12:07|INFO    |root                            |BAZARR Finished searching for Subtitles to upgrade. Check History for more information.|
04/08/2022 12:12:30|INFO    |root                            |BAZARR Finished searching for missing Series Subtitles. Check History for more information.|
04/08/2022 12:50:06|INFO    |root                            |BAZARR Running cache maintenance|
04/08/2022 14:34:57|INFO    |root                            |Using sucha again after 1 hour, (disabled because: ConnectTimeout)|
04/08/2022 14:34:57|INFO    |root                            |Using subscene again after 10 minutes, (disabled because: HTTPError)|
04/08/2022 14:35:07|WARNING |retry.api                       |HTTPSConnectionPool(host='argenteam.net', port=443): Read timed out. (read timeout=10), retrying in 5 seconds...|
04/08/2022 14:35:11|WARNING |retry.api                       |HTTPConnectionPool(host='sapidb.caretas.club', port=80): Max retries exceeded with url: /episode?query=Steins%3BGate+S01E01 (Caused by ConnectTimeoutError(<urllib3.connection.HTTPConnection object at 0x7feea20c3f10>, 'Connection to sapidb.caretas.club timed out. (connect timeout=10)')), retrying in 5 seconds...|
04/08/2022 14:35:17|WARNING |retry.api                       |HTTPSConnectionPool(host='www.subdivx.com', port=443): Read timed out. (read timeout=20), retrying in 5 seconds...|
04/08/2022 14:35:30|WARNING |retry.api                       |HTTPConnectionPool(host='sapidb.caretas.club', port=80): Max retries exceeded with url: /episode?query=Steins%3BGate+S01E01 (Caused by ConnectTimeoutError(<urllib3.connection.HTTPConnection object at 0x7feea2642310>, 'Connection to sapidb.caretas.club timed out. (connect timeout=10)')), retrying in 5 seconds...|
04/08/2022 14:35:49|INFO    |root                            |Throttling sucha for 1 hour, until 22/08/04 15:35, because of: ConnectTimeout. Exception info: MaxRetryError("HTTPConnectionPool(host='sapidb.caretas.club', port=80): Max retries exceeded with url: /episode?query=Steins%3BGate+S01E01 (Caused by ConnectTimeoutError(<urllib3.connection.HTTPConnection object at 0x7feea45d8220>, 'Connection to sapidb.caretas.club timed out. (connect timeout=10)'))")|
04/08/2022 14:38:11|WARNING |retry.api                       |HTTPSConnectionPool(host='www.subtitulamos.tv', port=443): Read timed out. (read timeout=10), retrying in 5 seconds...|
04/08/2022 14:46:10|INFO    |root                            |BAZARR Finished searching for missing Movies Subtitles. Check History for more information.|
04/08/2022 14:52:53|INFO    |root                            |Throttling subscene for 10 minutes, until 22/08/04 15:02, because of: ProviderError. Exception info: 'Something went wrong when trying to log in #1'|
04/08/2022 14:53:26|INFO    |root                            |Throttling subscene for 10 minutes, until 22/08/04 15:03, because of: ProviderError. Exception info: 'Something went wrong when trying to log in #1'|
04/08/2022 14:58:48|INFO    |root                            |BAZARR Finished searching for missing Series Subtitles. Check History for more information.|
04/08/2022 14:59:29|ERROR   |waitress                        |Exception while serving /api/socket.io/|'Traceback (most recent call last):\n  File "/app/bazarr/bin/bazarr/../libs/waitress/channel.py", line 397, in service\n    task.service()\n  File "/app/bazarr/bin/bazarr/../libs/waitress/task.py", line 168, in service\n    self.execute()\n  File "/app/bazarr/bin/bazarr/../libs/waitress/task.py", line 434, in execute\n    app_iter = self.channel.server.application(environ, start_response)\n  File "/app/bazarr/bin/bazarr/../libs/flask/app.py", line 2091, in __call__\n    return self.wsgi_app(environ, start_response)\n  File "/app/bazarr/bin/bazarr/../libs/flask_socketio/__init__.py", line 43, in __call__\n    return super(_SocketIOMiddleware, self).__call__(environ,\n  File "/app/bazarr/bin/bazarr/../libs/engineio/middleware.py", line 63, in __call__\n    return self.engineio_app.handle_request(environ, start_response)\n  File "/app/bazarr/bin/bazarr/../libs/socketio/server.py", line 597, in handle_request\n    return self.eio.handle_request(environ, start_response)\n  File "/app/bazarr/bin/bazarr/../libs/engineio/server.py", line 409, in handle_request\n    socket = self._get_socket(sid)\n  File "/app/bazarr/bin/bazarr/../libs/engineio/server.py", line 638, in _get_socket\n    raise KeyError(\'Session is disconnected\')\nKeyError: \'Session is disconnected\''|
04/08/2022 15:03:31|INFO    |root                            |Using subscene again after 10 minutes, (disabled because: ProviderError)|
04/08/2022 15:03:35|INFO    |root                            |Throttling subscene for 10 minutes, until 22/08/04 15:13, because of: ProviderError. Exception info: 'Something went wrong when trying to log in #1'|
04/08/2022 15:23:14|INFO    |root                            |Using subscene again after 10 minutes, (disabled because: ProviderError)|
04/08/2022 15:23:25|WARNING |retry.api                       |HTTPSConnectionPool(host='argenteam.net', port=443): Read timed out. (read timeout=10), retrying in 5 seconds...|
04/08/2022 15:23:35|WARNING |retry.api                       |HTTPSConnectionPool(host='www.subdivx.com', port=443): Read timed out. (read timeout=20), retrying in 5 seconds...|
04/08/2022 15:25:47|INFO    |root                            |Throttling subscene for 10 minutes, until 22/08/04 15:35, because of: ProviderError. Exception info: 'Something went wrong when trying to log in #1'|
04/08/2022 15:25:53|WARNING |retry.api                       |HTTPSConnectionPool(host='www.subtitulamos.tv', port=443): Read timed out. (read timeout=10), retrying in 5 seconds...|
04/08/2022 15:34:45|INFO    |root                            |BAZARR Finished searching for missing Series Subtitles. Check History for more information.|
04/08/2022 15:56:51|INFO    |root                            |Using sucha again after 1 hour, (disabled because: ConnectTimeout)|
04/08/2022 15:56:51|INFO    |root                            |Using subscene again after 10 minutes, (disabled because: ProviderError)|
04/08/2022 15:56:54|INFO    |root                            |BAZARR throttled providers have been reset.|
04/08/2022 15:57:00|INFO    |root                            |Bazarr is being restarted...|
04/08/2022 15:57:14|INFO    |root                            |BAZARR trying to connect to Sonarr SignalR feed...|
04/08/2022 15:57:14|INFO    |root                            |BAZARR trying to connect to Radarr SignalR feed...|
04/08/2022 15:57:14|INFO    |root                            |BAZARR is started and waiting for request on http://***.***.***.***:6767|
04/08/2022 15:57:14|INFO    |root                            |BAZARR SignalR client for Radarr is connected and waiting for events.|
04/08/2022 15:57:14|INFO    |root                            |BAZARR SignalR client for Sonarr is connected and waiting for events.|
04/08/2022 16:04:36|INFO    |root                            |Throttling subscene for 10 minutes, until 22/08/04 16:14, because of: ProviderError. Exception info: 'Something went wrong when trying to log in #1'|
04/08/2022 16:04:46|WARNING |retry.api                       |HTTPConnectionPool(host='sapidb.caretas.club', port=80): Max retries exceeded with url: /episode?query=Miss+Kobayashi%27s+Dragon+Maid+S01E01 (Caused by ConnectTimeoutError(<urllib3.connection.HTTPConnection object at 0x7f1410e65100>, 'Connection to sapidb.caretas.club timed out. (connect timeout=10)')), retrying in 5 seconds...|
04/08/2022 16:05:05|WARNING |retry.api                       |HTTPConnectionPool(host='sapidb.caretas.club', port=80): Max retries exceeded with url: /episode?query=Miss+Kobayashi%27s+Dragon+Maid+S01E01 (Caused by ConnectTimeoutError(<urllib3.connection.HTTPConnection object at 0x7f14191a7a30>, 'Connection to sapidb.caretas.club timed out. (connect timeout=10)')), retrying in 5 seconds...|
04/08/2022 16:05:24|INFO    |root                            |Throttling sucha for 1 hour, until 22/08/04 17:05, because of: ConnectTimeout. Exception info: MaxRetryError("HTTPConnectionPool(host='sapidb.caretas.club', port=80): Max retries exceeded with url: /episode?query=Miss+Kobayashi%27s+Dragon+Maid+S01E01 (Caused by ConnectTimeoutError(<urllib3.connection.HTTPConnection object at 0x7f1410aed190>, 'Connection to sapidb.caretas.club timed out. (connect timeout=10)'))")|
04/08/2022 16:14:42|INFO    |root                            |Using subscene again after 10 minutes, (disabled because: ProviderError)|
04/08/2022 16:14:47|INFO    |root                            |Throttling subscene for 10 minutes, until 22/08/04 16:24, because of: ProviderError. Exception info: 'Something went wrong when trying to log in #1'|
04/08/2022 16:50:35|ERROR   |engineio.server                 |Invalid session cWNc7BWfJ4zyJ0Y1AAAQ (further occurrences of this error will be logged with level INFO)|
04/08/2022 16:50:38|INFO    |root                            |Using subscene again after 10 minutes, (disabled because: ProviderError)|
04/08/2022 16:50:48|WARNING |retry.api                       |HTTPSConnectionPool(host='argenteam.net', port=443): Read timed out. (read timeout=10), retrying in 5 seconds...|
04/08/2022 16:50:58|WARNING |retry.api                       |HTTPSConnectionPool(host='www.subdivx.com', port=443): Read timed out. (read timeout=20), retrying in 5 seconds...|
04/08/2022 16:52:41|INFO    |root                            |Throttling subscene for 10 minutes, until 22/08/04 17:02, because of: ProviderError. Exception info: 'Something went wrong when trying to log in #1'|
04/08/2022 16:52:47|WARNING |retry.api                       |HTTPSConnectionPool(host='www.subtitulamos.tv', port=443): Read timed out. (read timeout=10), retrying in 5 seconds...|
04/08/2022 17:03:56|ERROR   |waitress                        |Exception while serving /api/socket.io/|'Traceback (most recent call last):\n  File "/app/bazarr/bin/bazarr/../libs/waitress/channel.py", line 397, in service\n    task.service()\n  File "/app/bazarr/bin/bazarr/../libs/waitress/task.py", line 168, in service\n    self.execute()\n  File "/app/bazarr/bin/bazarr/../libs/waitress/task.py", line 434, in execute\n    app_iter = self.channel.server.application(environ, start_response)\n  File "/app/bazarr/bin/bazarr/../libs/flask/app.py", line 2091, in __call__\n    return self.wsgi_app(environ, start_response)\n  File "/app/bazarr/bin/bazarr/../libs/flask_socketio/__init__.py", line 43, in __call__\n    return super(_SocketIOMiddleware, self).__call__(environ,\n  File "/app/bazarr/bin/bazarr/../libs/engineio/middleware.py", line 63, in __call__\n    return self.engineio_app.handle_request(environ, start_response)\n  File "/app/bazarr/bin/bazarr/../libs/socketio/server.py", line 597, in handle_request\n    return self.eio.handle_request(environ, start_response)\n  File "/app/bazarr/bin/bazarr/../libs/engineio/server.py", line 429, in handle_request\n    socket = self._get_socket(sid)\n  File "/app/bazarr/bin/bazarr/../libs/engineio/server.py", line 638, in _get_socket\n    raise KeyError(\'Session is disconnected\')\nKeyError: \'Session is disconnected\''|
04/08/2022 17:03:58|INFO    |root                            |Using subscene again after 10 minutes, (disabled because: ProviderError)|
04/08/2022 17:04:09|WARNING |retry.api                       |HTTPSConnectionPool(host='argenteam.net', port=443): Read timed out. (read timeout=10), retrying in 5 seconds...|
04/08/2022 17:04:19|WARNING |retry.api                       |HTTPSConnectionPool(host='www.subdivx.com', port=443): Read timed out. (read timeout=20), retrying in 5 seconds...|
04/08/2022 17:05:30|INFO    |root                            |Using sucha again after 1 hour, (disabled because: ConnectTimeout)|
04/08/2022 17:05:44|WARNING |retry.api                       |HTTPConnectionPool(host='sapidb.caretas.club', port=80): Max retries exceeded with url: /episode?query=Bungo+Stray+Dogs+S01E10 (Caused by ConnectTimeoutError(<urllib3.connection.HTTPConnection object at 0x7f1410c3f670>, 'Connection to sapidb.caretas.club timed out. (connect timeout=10)')), retrying in 5 seconds...|
04/08/2022 17:06:03|WARNING |retry.api                       |HTTPConnectionPool(host='sapidb.caretas.club', port=80): Max retries exceeded with url: /episode?query=Bungo+Stray+Dogs+S01E10 (Caused by ConnectTimeoutError(<urllib3.connection.HTTPConnection object at 0x7f1410e65340>, 'Connection to sapidb.caretas.club timed out. (connect timeout=10)')), retrying in 5 seconds...|
04/08/2022 17:06:23|INFO    |root                            |Throttling sucha for 1 hour, until 22/08/04 18:06, because of: ConnectTimeout. Exception info: MaxRetryError("HTTPConnectionPool(host='sapidb.caretas.club', port=80): Max retries exceeded with url: /episode?query=Bungo+Stray+Dogs+S01E10 (Caused by ConnectTimeoutError(<urllib3.connection.HTTPConnection object at 0x7f1410e74c40>, 'Connection to sapidb.caretas.club timed out. (connect timeout=10)'))")|
04/08/2022 17:06:48|WARNING |retry.api                       |HTTPSConnectionPool(host='www.subtitulamos.tv', port=443): Read timed out. (read timeout=10), retrying in 5 seconds...|
04/08/2022 17:08:49|ERROR   |waitress                        |Exception while serving /api/socket.io/|'Traceback (most recent call last):\n  File "/app/bazarr/bin/bazarr/../libs/waitress/channel.py", line 397, in service\n    task.service()\n  File "/app/bazarr/bin/bazarr/../libs/waitress/task.py", line 168, in service\n    self.execute()\n  File "/app/bazarr/bin/bazarr/../libs/waitress/task.py", line 434, in execute\n    app_iter = self.channel.server.application(environ, start_response)\n  File "/app/bazarr/bin/bazarr/../libs/flask/app.py", line 2091, in __call__\n    return self.wsgi_app(environ, start_response)\n  File "/app/bazarr/bin/bazarr/../libs/flask_socketio/__init__.py", line 43, in __call__\n    return super(_SocketIOMiddleware, self).__call__(environ,\n  File "/app/bazarr/bin/bazarr/../libs/engineio/middleware.py", line 63, in __call__\n    return self.engineio_app.handle_request(environ, start_response)\n  File "/app/bazarr/bin/bazarr/../libs/socketio/server.py", line 597, in handle_request\n    return self.eio.handle_request(environ, start_response)\n  File "/app/bazarr/bin/bazarr/../libs/engineio/server.py", line 429, in handle_request\n    socket = self._get_socket(sid)\n  File "/app/bazarr/bin/bazarr/../libs/engineio/server.py", line 638, in _get_socket\n    raise KeyError(\'Session is disconnected\')\nKeyError: \'Session is disconnected\''|
04/08/2022 18:07:07|ERROR   |waitress                        |Exception while serving /api/socket.io/|'Traceback (most recent call last):\n  File "/app/bazarr/bin/bazarr/../libs/waitress/channel.py", line 397, in service\n    task.service()\n  File "/app/bazarr/bin/bazarr/../libs/waitress/task.py", line 168, in service\n    self.execute()\n  File "/app/bazarr/bin/bazarr/../libs/waitress/task.py", line 434, in execute\n    app_iter = self.channel.server.application(environ, start_response)\n  File "/app/bazarr/bin/bazarr/../libs/flask/app.py", line 2091, in __call__\n    return self.wsgi_app(environ, start_response)\n  File "/app/bazarr/bin/bazarr/../libs/flask_socketio/__init__.py", line 43, in __call__\n    return super(_SocketIOMiddleware, self).__call__(environ,\n  File "/app/bazarr/bin/bazarr/../libs/engineio/middleware.py", line 63, in __call__\n    return self.engineio_app.handle_request(environ, start_response)\n  File "/app/bazarr/bin/bazarr/../libs/socketio/server.py", line 597, in handle_request\n    return self.eio.handle_request(environ, start_response)\n  File "/app/bazarr/bin/bazarr/../libs/engineio/server.py", line 429, in handle_request\n    socket = self._get_socket(sid)\n  File "/app/bazarr/bin/bazarr/../libs/engineio/server.py", line 638, in _get_socket\n    raise KeyError(\'Session is disconnected\')\nKeyError: \'Session is disconnected\''|
04/08/2022 18:29:07|INFO    |root                            |Using sucha again after 1 hour, (disabled because: ConnectTimeout)|
04/08/2022 18:29:18|WARNING |retry.api                       |HTTPSConnectionPool(host='argenteam.net', port=443): Read timed out. (read timeout=10), retrying in 5 seconds...|
04/08/2022 18:29:22|WARNING |retry.api                       |HTTPConnectionPool(host='sapidb.caretas.club', port=80): Max retries exceeded with url: /episode?query=Steins%3BGate+S01E01 (Caused by ConnectTimeoutError(<urllib3.connection.HTTPConnection object at 0x7f141077e820>, 'Connection to sapidb.caretas.club timed out. (connect timeout=10)')), retrying in 5 seconds...|
04/08/2022 18:29:28|WARNING |retry.api                       |HTTPSConnectionPool(host='www.subdivx.com', port=443): Read timed out. (read timeout=20), retrying in 5 seconds...|
04/08/2022 18:29:41|WARNING |retry.api                       |HTTPConnectionPool(host='sapidb.caretas.club', port=80): Max retries exceeded with url: /episode?query=Steins%3BGate+S01E01 (Caused by ConnectTimeoutError(<urllib3.connection.HTTPConnection object at 0x7f14109d1850>, 'Connection to sapidb.caretas.club timed out. (connect timeout=10)')), retrying in 5 seconds...|
04/08/2022 18:30:00|INFO    |root                            |Throttling sucha for 1 hour, until 22/08/04 19:30, because of: ConnectTimeout. Exception info: MaxRetryError("HTTPConnectionPool(host='sapidb.caretas.club', port=80): Max retries exceeded with url: /episode?query=Steins%3BGate+S01E01 (Caused by ConnectTimeoutError(<urllib3.connection.HTTPConnection object at 0x7f14109d1c10>, 'Connection to sapidb.caretas.club timed out. (connect timeout=10)'))")|
04/08/2022 18:32:06|WARNING |retry.api                       |HTTPSConnectionPool(host='www.subtitulamos.tv', port=443): Read timed out. (read timeout=10), retrying in 5 seconds...|
04/08/2022 18:32:14|WARNING |retry.api                       |HTTPSConnectionPool(host='subscene.com', port=443): Read timed out. (read timeout=10), retrying in 5 seconds...|
04/08/2022 18:34:50|WARNING |retry.api                       |HTTPSConnectionPool(host='subscene.com', port=443): Read timed out. (read timeout=10), retrying in 5 seconds...|
04/08/2022 18:36:08|WARNING |retry.api                       |HTTPSConnectionPool(host='subscene.com', port=443): Read timed out. (read timeout=10), retrying in 5 seconds...|
04/08/2022 18:36:29|WARNING |retry.api                       |HTTPSConnectionPool(host='subscene.com', port=443): Read timed out. (read timeout=10), retrying in 5 seconds...|
04/08/2022 18:51:40|INFO    |root                            |BAZARR Finished searching for missing Movies Subtitles. Check History for more information.|
04/08/2022 18:59:03|WARNING |retry.api                       |HTTPSConnectionPool(host='subscene.com', port=443): Read timed out. (read timeout=10), retrying in 5 seconds...|
04/08/2022 18:59:23|WARNING |retry.api                       |HTTPSConnectionPool(host='subscene.com', port=443): Read timed out. (read timeout=10), retrying in 5 seconds...|
04/08/2022 19:31:19|INFO    |root                            |Using sucha again after 1 hour, (disabled because: ConnectTimeout)|
04/08/2022 19:31:34|WARNING |retry.api                       |HTTPConnectionPool(host='sapidb.caretas.club', port=80): Max retries exceeded with url: /episode?query=Miss+Kobayashi%27s+Dragon+Maid+S01E08 (Caused by ConnectTimeoutError(<urllib3.connection.HTTPConnection object at 0x7f14109db370>, 'Connection to sapidb.caretas.club timed out. (connect timeout=10)')), retrying in 5 seconds...|
04/08/2022 19:31:53|WARNING |retry.api                       |HTTPConnectionPool(host='sapidb.caretas.club', port=80): Max retries exceeded with url: /episode?query=Miss+Kobayashi%27s+Dragon+Maid+S01E08 (Caused by ConnectTimeoutError(<urllib3.connection.HTTPConnection object at 0x7f1410c75130>, 'Connection to sapidb.caretas.club timed out. (connect timeout=10)')), retrying in 5 seconds...|
04/08/2022 19:32:12|INFO    |root                            |Throttling sucha for 1 hour, until 22/08/04 20:32, because of: ConnectTimeout. Exception info: MaxRetryError("HTTPConnectionPool(host='sapidb.caretas.club', port=80): Max retries exceeded with url: /episode?query=Miss+Kobayashi%27s+Dragon+Maid+S01E08 (Caused by ConnectTimeoutError(<urllib3.connection.HTTPConnection object at 0x7f140f394970>, 'Connection to sapidb.caretas.club timed out. (connect timeout=10)'))")|
04/08/2022 19:40:10|WARNING |retry.api                       |HTTPSConnectionPool(host='argenteam.net', port=443): Read timed out. (read timeout=10), retrying in 5 seconds...|
04/08/2022 19:55:08|INFO    |root                            |BAZARR Finished searching for missing Series Subtitles. Check History for more information.|
04/08/2022 20:45:38|INFO    |root                            |Using sucha again after 1 hour, (disabled because: ConnectTimeout)|
04/08/2022 21:29:07|INFO    |root                            |BAZARR Finished searching for missing Series Subtitles. Check History for more information.|
04/08/2022 21:51:40|INFO    |root                            |BAZARR Finished searching for missing Movies Subtitles. Check History for more information.|
